# 03001-1
1. Which exception or error will be thrown when a programmer attempts to run this code?
```java
public class Foo {
    static int[] a;
    static { a[0]=2; }
    public static void main( String[] args ) {}
}
```
- A. java.lang.StackOverflowError
- B. java.lang.IllegalStateException
- <mark>C. java.lang.ExceptionInInitializerError</mark>
- D. java.lang.ArrayIndexOutOfBoundsException

2. What is the result?
```java
Object[] myObjects = {//23
    new Integer(12),
    new String("foo"),
    new Integer(5),
    new Boolean(true)
};
Arrays.sort(myObjects);// 29
for(int i=0; i<myObjects.length; i++) {
    System.out.print(myObjects[i].toString());
    System.out.print(" ");
}
```
- A. Compilation fails due to an error in line 23.
- B. Compilation fails due to an error in line 29.
- <mark>C. A ClassCastException occurs in line 29.</mark>
- D. A ClassCastException occurs in line 31.
- E. The value of all four objects prints in natural order.

3. What is the result?
```java
public class Boxer1{ //1
    Integer i;
    int x;
    public Boxer1(int y) {
        x = i+y;
        System.out.println(x); 
    }
    public static void main(String[] args) {
        new Boxer1(new Integer(4));
    }
}
```
- A. The value "4" is printed at the command line.
- B. Compilation fails because of an error in line 5.
- C. Compilation fails because of an error in line 9.
- <mark>D. A NullPointerException occurs at runtime.</mark>
- E. A NumberFormatException occurs at runtime.
- F. An IllegalStateException occurs at runtime.

# 03001-3-1
1. What is the result?
```java
Float pi = new Float(3.14f);
if (pi > 3) {
    System.out.print("pi is bigger than 3. ");
}
else {
    System.out.print("pi is not bigger than 3. ");
}
finally {
    System.out.println("Have a nice day.");
}
```
- <mark>A. Compilation fails.</mark>
- B. pi is bigger than 3.
- C. An exception occurs at runtime.
- D. pi is bigger than 3. Have a nice day.
- E. pi is not bigger than 3. Have a nice day.

2. What is the result?
```java
public static void main(String[] args) {
    try {
        args = null;
        args[0] = "test";
        System.out.println(args[0]);
    } catch (Exception ex) {
        System.out.println("Exception");
    } catch (NullPointerException npe) {
        System.out.println("NullPointerException");
    }
}
```
- A. test
- B. Exception
- <mark>C. Compilation fails.</mark>
- D. NullPointerException

3. Under which three circumstances（情况） will the code on line 37 be executed? (Choose three.)
```java
// some code here //31
try {
// some code here // 33
} catch (SomeException se) {
// some code here //35
} finally {
// some code here 37
}
```
- A. The instance gets garbage collected.
- <mark>B. The code on line 33 throws an exception.</mark>
- <mark>C. The code on line 35 throws an exception.</mark>
- D. The code on line 31 throws an exception.
- <mark>E. The code on line 33 executes successfully.</mark>

4. What is the result?
```java
static void test() {
    try {
        String x = null;
        System.out.print(x.toString() + " ");
    }
    finally { System.out.print("finally "); }
}
public static void main(String[] args) {
    try { test(); }
    catch (Exception ex) { System.out.print("exception "); }
}
```
- A. null
- B. finally
- C. null finally
- D. Compilation fails.
- <mark>E. finally exception</mark>

5. If some sort of exception is thrown at line 34, which output is possible?
```java
try {
    // some code here //34
} catch (NullPointerException e1) {
    System.out.print("a");
} catch (Exception e2) {
    System.out.print("b");
} finally {
    System.out.print("c");
}
```
- A. a
- B. b
- C. c
- <mark>D. ac</mark>
- E. abc

# 03001-3-3
1. What is the result?
```java
static void test() throws Error {
    if (true) throw new AssertionError();
    System.out.print("test ");
}
public static void main(String[] args) {
    try { test(); }
    catch (Exception ex) { System.out.print("exception "); }
    System.out.print("end ");
}
```
- A. end
- B. Compilation fails.
- C. exception end
- D. exception test end
- <mark>E. A Throwable is thrown by main.</mark>
- F. An Exception is thrown by main.

2. Which two statements are true if a NullPointerException is thrown on line 3 of class C? (Choose two.)

> 图03001-3-3-2

```java
try {
    A a = new A();
    a.method1(); // 27
} catch (Exception e) {
    System.out.print("an error occurred"); // 29
}
```
- A. The application will crash.
- <mark>B. The code on line 29 will be executed.</mark>
- C. The code on line 5 of class A will execute.
- D. The code on line 5 of class B will execute.
- <mark>E. The exception will be propagated（传播） back to line 27.

# 03001-3-4
1. Which statement is true if a TestException is thrown on line 3 of class B?

> 图03001-3-4-1

```java
public void method() {//31
    A a = new A();
    a.method1();
}
```
- A. Line 33 must be called within a try block.
- <mark>B. The exception thrown by method1 in class A is not required to be caught.</mark>
- C. The method declared on line 31 must be declared to throw a RuntimeException.
- D. On line 5 of class A, the call to method2 of class B does not need to be placed in a try/catch block.

2. What is the result?
```java
static void test() throws RuntimeException {
    try {
        System.out.print("test ");
        throw new RuntimeException();
    }
    catch (Exception ex) { System.out.print("exception "); }
}
public static void main(String[] args) {
    try { test(); }
    catch (RuntimeException ex) { System.out.print("runtime "); }
    System.out.print("end ");
}
```
- A. test end
- B. Compilation fails.
- C. test runtime end
- <mark>D. test exception end</mark>
- E. A Throwable is thrown by main at runtime.

# 03001-4
1. Which statement is true?
```java
class TestException extends Exception { }
class A {
    public String sayHello(String name) throws TestException {
        if(name == null) throw new TestException();
        return "Hello " + name;
    }
}
public class TestA {
    public static void main(String[] args) {//9
        new A().sayHello("Aiko");//10
    }
}
```
- A. Compilation succeeds.
- B. Class A does not compile.
- C. The method declared on line 9 cannot be modified to throw TestException.
- <mark>D. TestA compiles if line 10 is enclosed in a try/catch block that catches TestException.</mark>

# 03001-5
1. What is the result?
```java
class A {
    public void process() { System.out.print("A,"); }
}
class B extends A {
    public void process() throws IOException { //14
        super.process();
        System.out.print("B,");
        throw new IOException();
    }
    public static void main(String[] args) {
        try { new B().process(); } //20
        catch (IOException e) { System.out.println("Exception"); }
    }
}
```
- A. Exception
- B. A,B,Exception
- C. Compilation fails because of an error in line 20.
- <mark>D. Compilation fails because of an error in line 14.</mark>
- E. A NullPointerException is thrown at runtime.

2. What is the result?
```java
static class A {
    void process() throws Exception { throw new Exception(); }//12
}
static class B extends A {
    void process() { System.out.println("B"); }//15
}
public static void main(String[] args) {
    new B().process();//18
}
```
- <mark>A. B</mark>
- B. The code runs with no output.
- C. Compilation fails because of an error in line 12.
- D. Compilation fails because of an error in line 15.
- E. Compilation fails because of an error in line 18.

3. What is the result?
```java
class X { public void foo() { System.out.print("X "); } } //12
public class SubB extends X {
    public void foo() throws RuntimeException {
        super.foo();
        if (true) throw new RuntimeException();//16
        System.out.print("B ");//17
    }
    public static void main(String[] args) {
        new SubB().foo();
    }
}
```
- <mark>A. X, followed by an Exception.</mark>
- B. No output, and an Exception is thrown.
- C. Compilation fails due to an error on line 14.
- D. Compilation fails due to an error on line 16.
- E. Compilation fails due to an error on line 17.
- F. X, followed by an Exception, followed by B.

4. What is the result?
```java
class A {
    void foo() throws Exception { throw new Exception(); }
}
class SubB2 extends A {
    void foo() { System.out.println("B "); } //9
}
class Tester {
    public static void main(String[] args) {
        A a = new SubB2();
        a.foo();//14
    }
}
```
- A. B
- B. B, followed by an Exception.
- C. Compilation fails due to an error on line 9.
- <mark>D. Compilation fails due to an error on line 14.</mark>
- E. An Exception is thrown with no other output.

> 在使用多态调用方法的时候，编译器实际上是从运行时类型中寻找这个方法声明的，所以如果编译时类型（父类类型）中，当前方法声明抛出一个受检异常，即使子类重写了父类方法并且没有声明抛出异常，这个异常依然是需要进行处理的，相应的，如果编译时类型就是子类本身，那么此时这个方法就不需要进行异常处理。
> 在多态中，方法看右边（运行时），属性看左边（编译时），方法异常看左边。

